Workbook

Sheet Calibration coeff overview
A1: Serial number | B1: Location | C1: Period | D1: Antifreeze % | E1: Density of antifreeze mixture at room temperature (kg/m3) | F1: Density for antifreeze mixture around 0 C (kg/m3) | G1: GEUS coefficient at room temperature (m/mV) | H1: GEUS coefficient around 0 C (m/mV) | I1: Density of water at room temperature (kg/m3) | J1: Ø&J coefficient at room temperature (m/mV) | K1: Multiplication factor | L1: Ø&J coefficient around 0 C when using antifreeze (m/mV) | M1: GEUS/Ø&J | N1: Difference (%)
A2: 591 | B2: KPC_U | C2: 2008 - | D2: 100 | E2: 1130 | F2: =E2+15 -> 1145 | G2: ='GEUS calibrations'!AA2 -> 1.0768514 | H2: =G2*E2/F2 -> 1.0627442 | I2: 998 | J2: ='Ørum&Jensen calibrations'!J2 -> 0.4425163 | K2: 2.5 | L2: =J2*I2/F2*K2 -> 0.96426041 | M2: =H2/L2 -> 1.102134 | N2: =100*(H2-L2)/L2 -> 10.213397
A3: 592 | B3: NUK_U | C3: 2007 - 2010 | D3: 100 | E3: 1130 | F3: =E3+15 -> 1145 | G3: ='GEUS calibrations'!AA3 -> #VALUE! | H3: =G3*E3/F3 -> #VALUE! | I3: 998 | J3: ='Ørum&Jensen calibrations'!J3 -> 0.42527235 | K3: 2.5 | L3: =J3*I3/F3*K3 -> 0.92668517 | M3: =H3/L3 -> #VALUE! | N3: =100*(H3-L3)/L3 -> #VALUE!
A4: 593 | B4: TAS_L | C4: 2007 - | D4: 100 | E4: 1130 | F4: =E4+15 -> 1145 | G4: ='GEUS calibrations'!AA4 -> #VALUE! | H4: =G4*E4/F4 -> #VALUE! | I4: 998 | J4: ='Ørum&Jensen calibrations'!J4 -> 0.4304131 | K4: 2.5 | L4: =J4*I4/F4*K4 -> 0.93788705 | M4: =H4/L4 -> #VALUE! | N4: =100*(H4-L4)/L4 -> #VALUE!
A5: 594 | B5: QAS_L | C5: 2007 - 2009 | D5: 100 | E5: 1130 | F5: =E5+15 -> 1145 | G5: ='GEUS calibrations'!AA5 -> #VALUE! | H5: =G5*E5/F5 -> #VALUE! | I5: 998 | J5: ='Ørum&Jensen calibrations'!J5 -> 0.43687648 | K5: 2.5 | L5: =J5*I5/F5*K5 -> 0.95197103 | M5: =H5/L5 -> #VALUE! | N5: =100*(H5-L5)/L5 -> #VALUE!
A6: 595 | B6: KAN_L | C6: 2008 - | D6: 100 | E6: 1130 | F6: =E6+15 -> 1145 | G6: ='GEUS calibrations'!AA6 -> 1.131999 | H6: =G6*E6/F6 -> 1.1171693 | I6: 998 | J6: ='Ørum&Jensen calibrations'!J6 -> 0.43873831 | K6: 2.5 | L6: =J6*I6/F6*K6 -> 0.95602802 | M6: =H6/L6 -> 1.1685529 | N6: =100*(H6-L6)/L6 -> 16.855292
A7: 596 | B7: TAS_U | C7: 2007 - | D7: 100 | E7: 1130 | F7: =E7+15 -> 1145 | G7: ='GEUS calibrations'!AA7 -> #VALUE! | H7: =G7*E7/F7 -> #VALUE! | I7: 998 | J7: ='Ørum&Jensen calibrations'!J7 -> 0.43093049 | K7: 2.5 | L7: =J7*I7/F7*K7 -> 0.93901448 | M7: =H7/L7 -> #VALUE! | N7: =100*(H7-L7)/L7 -> #VALUE!
A8: 597 | B8: NUK_L | C8: 2007 - 2010 | D8: 100 | E8: 1130 | F8: =E8+15 -> 1145 | G8: ='GEUS calibrations'!AA8 -> #VALUE! | H8: =G8*E8/F8 -> #VALUE! | I8: 998 | J8: ='Ørum&Jensen calibrations'!J8 -> 0.43162413 | K8: 2.5 | L8: =J8*I8/F8*K8 -> 0.94052594 | M8: =H8/L8 -> #VALUE! | N8: =100*(H8-L8)/L8 -> #VALUE!
A9: 598 | B9: ZAK_M | C9: 2008 - | D9: 100 | E9: 1130 | F9: =E9+15 -> 1145 | G9: ='GEUS calibrations'!AA9 -> #VALUE! | H9: =G9*E9/F9 -> #VALUE! | I9: 998 | J9: ='Ørum&Jensen calibrations'!J9 -> 0.43437945 | K9: 2.5 | L9: =J9*I9/F9*K9 -> 0.94652989 | M9: =H9/L9 -> #VALUE! | N9: =100*(H9-L9)/L9 -> #VALUE!
A10: 5104 | B10: SCO_U? | C10: 2008 - | D10: 100 | E10: 1130 | F10: =E10+15 -> 1145 | G10: ='GEUS calibrations'!AA10 -> #VALUE! | H10: =G10*E10/F10 -> #VALUE! | I10: 998 | J10: ='Ørum&Jensen calibrations'!J10 -> 0.43893195 | K10: 2.5 | L10: =J10*I10/F10*K10 -> 0.95644998 | M10: =H10/L10 -> #VALUE! | N10: =100*(H10-L10)/L10 -> #VALUE!
A11: 5105 | B11: MAL | C11: 2008 - 2008 | D11: 100 | E11: 1130 | F11: =E11+15 -> 1145 | G11: ='GEUS calibrations'!AA11 -> #VALUE! | H11: =G11*E11/F11 -> #VALUE! | I11: 998 | J11: ='Ørum&Jensen calibrations'!J11 -> 0.43724301 | K11: 2.5 | L11: =J11*I11/F11*K11 -> 0.9527697 | M11: =H11/L11 -> #VALUE! | N11: =100*(H11-L11)/L11 -> #VALUE!
A12: 5112 | B12: KPC_L | C12: 2008 - | D12: 100 | E12: 1130 | F12: =E12+15 -> 1145 | G12: ='GEUS calibrations'!AA12 -> 1.1159917 | H12: =G12*E12/F12 -> 1.1013717 | I12: 998 | J12: ='Ørum&Jensen calibrations'!J12 -> 0.442037 | K12: 2.5 | L12: =J12*I12/F12*K12 -> 0.963216 | M12: =H12/L12 -> 1.1434317 | N12: =100*(H12-L12)/L12 -> 14.343167
A13: 5113 | B13: QAS_U | C13: 2008 - | D13: 100 | E13: 1130 | F13: =E13+15 -> 1145 | G13: ='GEUS calibrations'!AA13 -> 1.1116194 | H13: =G13*E13/F13 -> 1.0970567 | I13: 998 | J13: ='Ørum&Jensen calibrations'!J13 -> 0.44341866 | K13: 2.5 | L13: =J13*I13/F13*K13 -> 0.96622668 | M13: =H13/L13 -> 1.135403 | N13: =100*(H13-L13)/L13 -> 13.540299
... A21: 5138 | B21: MIT | C21: 2009 - | D21: 50 | E21: 1077 | F21: =E21+15 -> 1092 | G21: ='GEUS calibrations'!AA21 -> 1.1236937 | H21: =G21*E21/F21 -> 1.1082584 | I21: 998 | J21: ='Ørum&Jensen calibrations'!J21 -> 0.43952078 | K21: 2.5 | L21: =J21*I21/F21*K21 -> 1.0042164 | M21: =H21/L21 -> 1.1036051 | N21: =100*(H21-L21)/L21 -> 10.360511
A22: 5154 | B22: NUK_U? | C22: 2010 - | D22: 50 | E22: 1077 | F22: =E22+15 -> 1092 | G22: ='GEUS calibrations'!AA22 -> #VALUE! | H22: =G22*E22/F22 -> #VALUE! | I22: 998 | J22: ='Ørum&Jensen calibrations'!J22 -> 0.43230581 | K22: 2.5 | L22: =J22*I22/F22*K22 -> 0.98773168
A23: 5155 | D23: 50 | E23: 1077 | F23: =E23+15 -> 1092 | G23: ='GEUS calibrations'!AA23 -> #VALUE! | H23: =G23*E23/F23 -> #VALUE! | I23: 998 | J23: ='Ørum&Jensen calibrations'!J23 -> 0.4358049 | K23: 2.5 | L23: =J23*I23/F23*K23 -> 0.9957264
A24: 5156 | B24: NUK_L? | C24: 2010 - | D24: 50 | E24: 1077 | F24: =E24+15 -> 1092 | G24: ='GEUS calibrations'!AA24 -> #VALUE! | H24: =G24*E24/F24 -> #VALUE! | I24: 998 | J24: ='Ørum&Jensen calibrations'!J24 -> 0.42932014 | K24: 2.5 | L24: =J24*I24/F24*K24 -> 0.98091003
A25: 5157 | D25: 50 | E25: 1077 | F25: =E25+15 -> 1092 | G25: ='GEUS calibrations'!AA25 -> #VALUE! | H25: =G25*E25/F25 -> #VALUE! | I25: 998 | J25: ='Ørum&Jensen calibrations'!J25 -> 0.39617806 | K25: 2.5 | L25: =J25*I25/F25*K25 -> 0.90518705
A26: 5158 | B26: THU_U | C26: 2010 - | D26: 50 | E26: 1078 | F26: =E26+15 -> 1093 | G26: ='GEUS calibrations'!AA26 -> #VALUE! | H26: =G26*E26/F26 -> #VALUE! | I26: 998 | J26: ='Ørum&Jensen calibrations'!J26 -> 0.4398963 | K26: 2.5 | L26: =J26*I26/F26*K26 -> 1.0041549
A27: 5157 | B27: ? | C27: 2011- | D27: 50 | E27: 1077 | F27: =E27+15 -> 1092 | G27: ='GEUS calibrations'!AA27 -> 1.1743239 | H27: =G27*E27/F27 -> 1.158193 | I27: 998 | J27: ='Ørum&Jensen calibrations'!J3 -> 0.42527235 | K27: 2.5 | L27: =J27*I27/F27*K27 -> 0.97166165 | M27: =H27/L27 -> 1.1919715 | N27: =100*(H27-L27)/L27 -> 19.197154

Sheet GEUS calibrations
A1: Serial number | B1: Date | C1: Temperature (C) | D1: Air pressure (hPa) | E1: Height (m) | P1: Voltage (mV) | AA1: Slope | AB1: Standard error | AC1: R^2
A2: 591 output (mV) | B2: 9 June 2008 | C2: 20 | D2: 1018 | E2: 1.1 | F2: 3.22 | G2: 6.42 | H2: 8.8 | I2: 11.14 | J2: 13.15 | K2: 15.2 | P2: 1.13 | Q2: 3.07 | R2: 6.02 | S2: 8.21 | T2: 10.47 | U2: 12.31 | V2: 14.19 | AA2: =INDEX(LINEST($E2:$K2,$P2:$V2,,TRUE()),1) -> 1.0768514 | AB2: =INDEX(LINEST($E2:$K2,$P2:$V2,,TRUE()),2) -> 0.0030003277 | AC2: =INDEX(LINEST($E2:$K2,$P2:$V2,,TRUE()),3) -> 0.99996119
A3: 592 output (mV) | AA3: =INDEX(LINEST($E3:$O3,$P3:$Z3,,TRUE()),1) -> #VALUE! | AB3: =INDEX(LINEST($E3:$O3,$P3:$Z3,,TRUE()),2) -> #VALUE! | AC3: =INDEX(LINEST($E3:$O3,$P3:$Z3,,TRUE()),3) -> #VALUE!
A4: 593 output (mV) | AA4: =INDEX(LINEST($E4:$O4,$P4:$Z4,,TRUE()),1) -> #VALUE! | AB4: =INDEX(LINEST($E4:$O4,$P4:$Z4,,TRUE()),2) -> #VALUE! | AC4: =INDEX(LINEST($E4:$O4,$P4:$Z4,,TRUE()),3) -> #VALUE!
A5: 594 output (mV) | AA5: =INDEX(LINEST($E5:$O5,$P5:$Z5,,TRUE()),1) -> #VALUE! | AB5: =INDEX(LINEST($E5:$O5,$P5:$Z5,,TRUE()),2) -> #VALUE! | AC5: =INDEX(LINEST($E5:$O5,$P5:$Z5,,TRUE()),3) -> #VALUE!
A6: 595 output (mV) | B6: 19 Aug 2008 | C6: 23 | D6: 1003 | E6: 0.58 | F6: 5.2 | G6: 10.07 | H6: 15.06 | I6: 18.6 | P6: 0.47 | Q6: 4.68 | R6: 8.85 | S6: 13.29 | T6: 16.44 | AA6: =INDEX(LINEST($E6:$I6,$P6:$T6,,TRUE()),1) -> 1.131999 | AB6: =INDEX(LINEST($E6:$I6,$P6:$T6,,TRUE()),2) -> 0.0054842685 | AC6: =INDEX(LINEST($E6:$I6,$P6:$T6,,TRUE()),3) -> 0.99992959
A7: 596 output (mV) | AA7: =INDEX(LINEST($E7:$O7,$P7:$Z7,,TRUE()),1) -> #VALUE! | AB7: =INDEX(LINEST($E7:$O7,$P7:$Z7,,TRUE()),2) -> #VALUE! | AC7: =INDEX(LINEST($E7:$O7,$P7:$Z7,,TRUE()),3) -> #VALUE!
A8: 597 output (mV) | AA8: =INDEX(LINEST($E8:$O8,$P8:$Z8,,TRUE()),1) -> #VALUE! | AB8: =INDEX(LINEST($E8:$O8,$P8:$Z8,,TRUE()),2) -> #VALUE! | AC8: =INDEX(LINEST($E8:$O8,$P8:$Z8,,TRUE()),3) -> #VALUE!
A9: 598 output (mV) | AA9: =INDEX(LINEST($E9:$O9,$P9:$Z9,,TRUE()),1) -> #VALUE! | AB9: =INDEX(LINEST($E9:$O9,$P9:$Z9,,TRUE()),2) -> #VALUE! | AC9: =INDEX(LINEST($E9:$O9,$P9:$Z9,,TRUE()),3) -> #VALUE!
A10: 5104 output (mV) | AA10: =INDEX(LINEST($E10:$O10,$P10:$Z10,,TRUE()),1) -> #VALUE! | AB10: =INDEX(LINEST($E10:$O10,$P10:$Z10,,TRUE()),2) -> #VALUE! | AC10: =INDEX(LINEST($E10:$O10,$P10:$Z10,,TRUE()),3) -> #VALUE!
A11: 5105 output (mV) | AA11: =INDEX(LINEST($E11:$O11,$P11:$Z11,,TRUE()),1) -> #VALUE! | AB11: =INDEX(LINEST($E11:$O11,$P11:$Z11,,TRUE()),2) -> #VALUE! | AC11: =INDEX(LINEST($E11:$O11,$P11:$Z11,,TRUE()),3) -> #VALUE!
A12: 5112 output (mV) | B12: 2008 | C12: ? | D12: 1011 | E12: 5 | F12: 10 | G12: 15 | H12: 19 | P12: 4.24 | Q12: 8.67 | R12: 13.12 | S12: 16.8 | AA12: =INDEX(LINEST($E12:$H12,$P12:$S12,,TRUE()),1) -> 1.1159917 | AB12: =INDEX(LINEST($E12:$H12,$P12:$S12,,TRUE()),2) -> 0.0064320186 | AC12: =INDEX(LINEST($E12:$H12,$P12:$S12,,TRUE()),3) -> 0.99993357
A13: 5113 output (mV) | B13: 11 Jul 2008 | C13: ? | D13: 1002 | E13: 3.73 | F13: 7.16 | G13: 10.41 | H13: 14.54 | I13: 19.16 | P13: 3.59 | Q13: 6.69 | R13: 9.59 | S13: 13.33 | T13: 17.47 | AA13: =INDEX(LINEST($E13:$I13,$P13:$T13,,TRUE()),1) -> 1.1116194 | AB13: =INDEX(LINEST($E13:$H13,$P13:$S13,,TRUE()),2) -> 0.0021600208 | AC13: =INDEX(LINEST($E13:$H13,$P13:$S13,,TRUE()),3) -> 0.99999244
A14: 5114 output (mV) | B14: 2008 | C14: ? | D14: 1011 | E14: 5 | F14: 10 | G14: 15 | H14: 19 | P14: 4.56 | Q14: 9.03 | R14: 13.51 | S14: 17.09 | AA14: =INDEX(LINEST($E14:$H14,$P14:$S14,,TRUE()),1) -> 1.1171914 | AB14: =INDEX(LINEST($E14:$H14,$P14:$S14,,TRUE()),2) -> 0.0003518956 | AC14: =INDEX(LINEST($E14:$H14,$P14:$S14,,TRUE()),3) -> 0.9999998
A15: 5115 output (mV) | AA15: =INDEX(LINEST($E15:$O15,$P15:$Z15,,TRUE()),1) -> #VALUE! | AB15: =INDEX(LINEST($E15:$O15,$P15:$Z15,,TRUE()),2) -> #VALUE! | AC15: =INDEX(LINEST($E15:$O15,$P15:$Z15,,TRUE()),3) -> #VALUE!
A16: 5116 output (mV) | B16: 28 Jul 2009 | C16: ? | D16: 1015 | E16: 1 | F16: 3 | G16: 6 | H16: 9.18 | I16: 10.6 | J16: 13.2 | K16: 17 | L16: 19.25 | P16: 1.12 | Q16: 2.8 | R16: 5.28 | S16: 8.01 | T16: 9.21 | U16: 11.42 | V16: 14.67 | W16: 16.59 | AA16: =INDEX(LINEST($E16:$L16,$P16:$W16,,TRUE()),1) -> 1.1788016 | AB16: =INDEX(LINEST($E16:$L16,$P16:$W16,,TRUE()),2) -> 0.0023895951 | AC16: =INDEX(LINEST($E16:$L16,$P16:$W16,,TRUE()),3) -> 0.99997534
A17: 5117 output (mV) | AA17: =INDEX(LINEST($E17:$N17,$P17:$Z17,,TRUE()),1) -> #VALUE! | AB17: =INDEX(LINEST($E17:$N17,$P17:$Z17,,TRUE()),2) -> #VALUE! | AC17: =INDEX(LINEST($E17:$N17,$P17:$Z17,,TRUE()),3) -> #VALUE!
A18: 5135 output (mV) | B18: 8 Apr 2009 | C18: ? | D18: ? | E18: 1 | F18: 3 | G18: 5 | H18: 7 | I18: 10 | J18: 13 | K18: 15 | L18: 17 | P18: 1.61 | Q18: 3.32 | R18: 5.07 | S18: 6.77 | T18: 9.32 | U18: 11.81 | V18: 13.56 | W18: 15.26 | AA18: =INDEX(LINEST($E18:$L18,$P18:$W18,,TRUE()),1) -> 1.1742435 | AB18: =INDEX(LINEST($E18:$L18,$P18:$W18,,TRUE()),2) -> 0.0025313661 | AC18: =INDEX(LINEST($E18:$L18,$P18:$W18,,TRUE()),3) -> 0.99997212
A19: 5136 output (mV) | AA19: =INDEX(LINEST($E19:$N19,$P19:$Z19,,TRUE()),1) -> #VALUE! | AB19: =INDEX(LINEST($E19:$N19,$P19:$Z19,,TRUE()),2) -> #VALUE! | AC19: =INDEX(LINEST($E19:$N19,$P19:$Z19,,TRUE()),3) -> #VALUE!
A20: 5137 output (mV) | B20: 8 Apr 2009 | C20: ? | D20: ? | E20: 1 | F20: 3 | G20: 5 | H20: 7 | I20: 10 | J20: 13 | K20: 15 | L20: 17 | P20: 1.62 | Q20: 3.25 | R20: 5.03 | S20: 6.69 | T20: 9.2 | U20: 11.72 | V20: 13.42 | W20: 15.11 | AA20: =INDEX(LINEST($E20:$L20,$P20:$W20,,TRUE()),1) -> 1.1856745 | AB20: =INDEX(LINEST($E20:$L20,$P20:$W20,,TRUE()),2) -> 0.0026099037 | AC20: =INDEX(LINEST($E20:$L20,$P20:$W20,,TRUE()),3) -> 0.99997093
A21: 5138 output (mV) | B21: 8 Apr 2009 | C21: ? | D21: ? | E21: 1 | F21: 3 | G21: 5 | H21: 7 | I21: 10 | J21: 13 | K21: 15 | L21: 17 | P21: 1.85 | Q21: 3.64 | R21: 5.41 | S21: 7.2 | T21: 9.84 | U21: 12.51 | V21: 14.31 | W21: 16.11 | AA21: =INDEX(LINEST($E21:$L21,$P21:$W21,,TRUE()),1) -> 1.1236937 | AB21: =INDEX(LINEST($E21:$L21,$P21:$W21,,TRUE()),2) -> 0.0012524657 | AC21: =INDEX(LINEST($E21:$L21,$P21:$W21,,TRUE()),3) -> 0.99999255
A22: 5154 output (mV) | AA22: =INDEX(LINEST($E22:$O22,$P22:$Z22,,TRUE()),1) -> #VALUE! | AB22: =INDEX(LINEST($E22:$O22,$P22:$Z22,,TRUE()),2) -> #VALUE! | AC22: =INDEX(LINEST($E22:$O22,$P22:$Z22,,TRUE()),3) -> #VALUE!
A23: 5155 output (mV) | AA23: =INDEX(LINEST($E23:$O23,$P23:$Z23,,TRUE()),1) -> #VALUE! | AB23: =INDEX(LINEST($E23:$O23,$P23:$Z23,,TRUE()),2) -> #VALUE! | AC23: =INDEX(LINEST($E23:$O23,$P23:$Z23,,TRUE()),3) -> #VALUE!
A24: 5156 output (mV) | AA24: =INDEX(LINEST($E24:$O24,$P24:$Z24,,TRUE()),1) -> #VALUE! | AB24: =INDEX(LINEST($E24:$O24,$P24:$Z24,,TRUE()),2) -> #VALUE! | AC24: =INDEX(LINEST($E24:$O24,$P24:$Z24,,TRUE()),3) -> #VALUE!
A25: 5157 output (mV) | AA25: =INDEX(LINEST($E25:$O25,$P25:$Z25,,TRUE()),1) -> #VALUE! | AB25: =INDEX(LINEST($E25:$O25,$P25:$Z25,,TRUE()),2) -> #VALUE! | AC25: =INDEX(LINEST($E25:$O25,$P25:$Z25,,TRUE()),3) -> #VALUE!
A26: 5158 output (mV) | AA26: =INDEX(LINEST($E26:$O26,$P26:$Z26,,TRUE()),1) -> #VALUE! | AB26: =INDEX(LINEST($E26:$O26,$P26:$Z26,,TRUE()),2) -> #VALUE! | AC26: =INDEX(LINEST($E26:$O26,$P26:$Z26,,TRUE()),3) -> #VALUE!
A27: 592 output (mV) | B27: 20/3 2011 | E27: 0 | F27: 1 | G27: 3 | H27: 5 | I27: 7 | J27: 9 | K27: 11 | L27: 13 | M27: 15 | N27: 17 | O27: 18.7 | P27: 0 | Q27: 0.6 | R27: 2.35 | S27: 4.05 | T27: 5.73 | U27: 7.52 | V27: 9.2 | W27: 10.88 | X27: 12.6 | Y27: 14.33 | Z27: 15.78 | AA27: =INDEX(LINEST($E27:$O27,$P27:$Z27,,TRUE()),1) -> 1.1743239 | AB27: =INDEX(LINEST($E27:$O27,$P27:$Z27,,TRUE()),2) -> 0.0047445509 | AC27: =INDEX(LINEST($E27:$O27,$P27:$Z27,,TRUE()),3) -> 0.99985311

Sheet Ørum&Jensen calibrations
A1: Serial number | B1: Temperature (C) | C1: Air pressure (hPa) | D1: 0 | E1: 10 | F1: 20 | G1: 30 | H1: 40 | I1: 50 | J1: Slope | K1: Standard error | L1: R^2 | M1: Located where in 2020 | N1: Located where in 2021 | O1: Located where in 2022 | P1: Located where in 2023 | Q1: Located where in 2024 | R1: Located where 2025 | S1: Located where 2026 | T1: Comment
A2: 5002 output (mV) | B2: 29 | C2: 1012 | D2: 1.12 | E2: 23.78 | F2: 46.43 | G2: 69.03 | H2: 91.59 | I2: 114.1 | J2: =INDEX(LINEST($D$1:$I$1,$D2:$I2,,TRUE()),1) -> 0.4425163 | K2: =INDEX(LINEST($D$1:$I$1,$D2:$I2,,TRUE()),2) -> 0.00028550368 | L2: =INDEX(LINEST($D$1:$I$1,$D2:$I2,,TRUE()),3) -> 0.99999833 | N2: QAS_L | O2: QAS_L
A3: 5004 output (mV) | B3: 29 | C3: 1012 | D3: 0.75 | E3: 24.35 | F3: 47.92 | G3: 71.44 | H3: 94.91 | I3: 118.31 | J3: =INDEX(LINEST($D$1:$I$1,$D3:$I3,,TRUE()),1) -> 0.42527235 | K3: =INDEX(LINEST($D$1:$I$1,$D3:$I3,,TRUE()),2) -> 0.00033181158 | L3: =INDEX(LINEST($D$1:$I$1,$D3:$I3,,TRUE()),3) -> 0.99999756
A4: 5005 output (mV) | B4: 29 | C4: 1012 | D4: 0.44 | E4: 23.77 | F4: 47.06 | G4: 70.3 | H4: 93.48 | I4: 116.6 | J4: =INDEX(LINEST($D$1:$I$1,$D4:$I4,,TRUE()),1) -> 0.4304131 | K4: =INDEX(LINEST($D$1:$I$1,$D4:$I4,,TRUE()),2) -> 0.00036063867 | L4: =INDEX(LINEST($D$1:$I$1,$D4:$I4,,TRUE()),3) -> 0.99999719
A5: 5006 output (mV) | B5: 22.7 | C5: 1005.9 | D5: 0.54 | E5: 23.51 | F5: 46.45 | G5: 69.35 | H5: 92.19 | I5: 114.98 | J5: =INDEX(LINEST($D$1:$I$1,$D5:$I5,,TRUE()),1) -> 0.43687648 | K5: =INDEX(LINEST($D$1:$I$1,$D5:$I5,,TRUE()),2) -> 0.0003248805 | L5: =INDEX(LINEST($D$1:$I$1,$D5:$I5,,TRUE()),3) -> 0.99999779 | M5: KPC_U | N5: KPC_U | O5: KPC_U
A6: 5007 output (mV) | B6: 22.7 | C6: 1005.9 | D6: 0.45 | E6: 23.34 | F6: 46.18 | G6: 68.98 | H6: 91.72 | I6: 114.41 | J6: =INDEX(LINEST($D$1:$I$1,$D6:$I6,,TRUE()),1) -> 0.43873831 | K6: =INDEX(LINEST($D$1:$I$1,$D6:$I6,,TRUE()),2) -> 0.00035169844 | L6: =INDEX(LINEST($D$1:$I$1,$D6:$I6,,TRUE()),3) -> 0.99999743
A7: 5011 output (mV) | B7: 22 | C7: 1039.5 | D7: 0.645 | E7: 23.935 | F7: 47.196 | G7: 70.407 | H7: 93.566 | I7: 116.663 | J7: =INDEX(LINEST($D$1:$I$1,$D7:$I7,,TRUE()),1) -> 0.43093049 | K7: =INDEX(LINEST($D$1:$I$1,$D7:$I7,,TRUE()),2) -> 0.0003337589 | L7: =INDEX(LINEST($D$1:$I$1,$D7:$I7,,TRUE()),3) -> 0.9999976 | P7: QAS_L
A8: 5012 output (mV) | B8: 22 | C8: 1039.5 | D8: 0.806 | E8: 24.078 | F8: 47.309 | G8: 70.483 | H8: 93.596 | I8: 116.638 | J8: =INDEX(LINEST($D$1:$I$1,$D8:$I8,,TRUE()),1) -> 0.43162413 | K8: =INDEX(LINEST($D$1:$I$1,$D8:$I8,,TRUE()),2) -> 0.00039500385 | L8: =INDEX(LINEST($D$1:$I$1,$D8:$I8,,TRUE()),3) -> 0.99999665 | Q8: KAN_Lv3
A9: 5013 output (mV) | B9: 22 | C9: 1039.5 | D9: 1.128 | E9: 24.246 | F9: 47.321 | G9: 70.346 | H9: 93.316 | I9: 116.23 | J9: =INDEX(LINEST($D$1:$I$1,$D9:$I9,,TRUE()),1) -> 0.43437945 | K9: =INDEX(LINEST($D$1:$I$1,$D9:$I9,,TRUE()),2) -> 0.00035459899 | L9: =INDEX(LINEST($D$1:$I$1,$D9:$I9,,TRUE()),3) -> 0.99999733
A10: 5014 output (mV) | B10: 22 | C10: 1003.5 | D10: -1.655 | E10: 21.23 | F10: 44.06 | G10: 66.842 | H10: 89.582 | I10: 112.255 | J10: =INDEX(LINEST($D$1:$I$1,$D10:$I10,,TRUE()),1) -> 0.43893195 | K10: =INDEX(LINEST($D$1:$I$1,$D10:$I10,,TRUE()),2) -> 0.00035714662 | L10: =INDEX(LINEST($D$1:$I$1,$D10:$I10,,TRUE()),3) -> 0.99999735
A11: 5015 output (mV) | B11: 22 | C11: 1003.8 | D11: -1.332 | E11: 21.605 | F11: 44.493 | G11: 67.362 | H11: 90.359 | I11: 112.935 | J11: =INDEX(LINEST($D$1:$I$1,$D11:$I11,,TRUE()),1) -> 0.43724301 | K11: =INDEX(LINEST($D$1:$I$1,$D11:$I11,,TRUE()),2) -> 0.00050112145 | L11: =INDEX(LINEST($D$1:$I$1,$D11:$I11,,TRUE()),3) -> 0.99999475
A12: 5016 output (mV) | B12: 22 | C12: 1003.5 | D12: -1.346 | E12: 21.363 | F12: 44.035 | G12: 66.665 | H12: 89.242 | I12: 111.758 | J12: =INDEX(LINEST($D$1:$I$1,$D12:$I12,,TRUE()),1) -> 0.442037 | K12: =INDEX(LINEST($D$1:$I$1,$D12:$I12,,TRUE()),2) -> 0.00034376821 | L12: =INDEX(LINEST($D$1:$I$1,$D12:$I12,,TRUE()),3) -> 0.99999758
A13: 5018 output (mV) | B13: 25 | C13: 1002.7 | D13: -0.085 | E13: 22.556 | F13: 45.155 | G13: 67.711 | H13: 90.214 | I13: 112.673 | J13: =INDEX(LINEST($D$1:$I$1,$D13:$I13,,TRUE()),1) -> 0.44341866 | K13: =INDEX(LINEST($D$1:$I$1,$D13:$I13,,TRUE()),2) -> 0.00033192814 | L13: =INDEX(LINEST($D$1:$I$1,$D13:$I13,,TRUE()),3) -> 0.99999776
A14: 5019 output (mV) | B14: 25 | C14: 1002.7 | D14: -0.008 | E14: 22.645 | F14: 45.262 | G14: 67.835 | H14: 90.362 | I14: 112.831 | J14: =INDEX(LINEST($D$1:$I$1,$D14:$I14,,TRUE()),1) -> 0.44308243 | K14: =INDEX(LINEST($D$1:$I$1,$D14:$I14,,TRUE()),2) -> 0.00032835194 | L14: =INDEX(LINEST($D$1:$I$1,$D14:$I14,,TRUE()),3) -> 0.9999978 | M14: MIT
A15: 5020 output (mV) | B15: 24 | C15: 1025.5 | D15: 0.206 | E15: 24.355 | F15: 48.464 | G15: 72.514 | H15: 96.498 | I15: 120.415 | J15: =INDEX(LINEST($D$1:$I$1,$D15:$I15,,TRUE()),1) -> 0.41591073 | K15: =INDEX(LINEST($D$1:$I$1,$D15:$I15,,TRUE()),2) -> 0.00037531109 | L15: =INDEX(LINEST($D$1:$I$1,$D15:$I15,,TRUE()),3) -> 0.99999674
A16: 5021 output (mV) | B16: 24 | C16: 1022.1 | D16: 0.329 | E16: 22.652 | F16: 44.95 | G16: 67.215 | H16: 89.435 | I16: 111.608 | J16: =INDEX(LINEST($D$1:$I$1,$D16:$I16,,TRUE()),1) -> 0.44928807 | K16: =INDEX(LINEST($D$1:$I$1,$D16:$I16,,TRUE()),2) -> 0.00028081882 | L16: =INDEX(LINEST($D$1:$I$1,$D16:$I16,,TRUE()),3) -> 0.99999844
A17: 5022 output (mV) | B17: 24 | C17: 1022.1 | D17: 0.015 | E17: 22.613 | F17: 45.178 | G17: 67.704 | H17: 90.185 | I17: 112.615 | J17: =INDEX(LINEST($D$1:$I$1,$D17:$I17,,TRUE()),1) -> 0.44402525 | K17: =INDEX(LINEST($D$1:$I$1,$D17:$I17,,TRUE()),2) -> 0.00030296173 | L17: =INDEX(LINEST($D$1:$I$1,$D17:$I17,,TRUE()),3) -> 0.99999814
A18: 5023 output (mV) | B18: 24 | C18: 1022.1 | D18: -0.056 | E18: 22.682 | F18: 45.382 | G18: 68.038 | H18: 90.641 | I18: 113.186 | J18: =INDEX(LINEST($D$1:$I$1,$D18:$I18,,TRUE()),1) -> 0.44150393 | K18: =INDEX(LINEST($D$1:$I$1,$D18:$I18,,TRUE()),2) -> 0.00034464551 | L18: =INDEX(LINEST($D$1:$I$1,$D18:$I18,,TRUE()),3) -> 0.99999756
A19: 5025 output (mV) | B19: 31.5 | C19: 1023.5 | D19: 0.58 | E19: 23.23 | F19: 45.86 | G19: 68.49 | H19: 90.05 | I19: 113.51 | J19: =INDEX(LINEST($D$1:$I$1,$D19:$I19,,TRUE()),1) -> 0.44427683 | K19: =INDEX(LINEST($D$1:$I$1,$D19:$I19,,TRUE()),2) -> 0.0018914614 | L19: =INDEX(LINEST($D$1:$I$1,$D19:$I19,,TRUE()),3) -> 0.9999275 | M19: THU_U | N19: THU_U
A20: 5026 output (mV) | B20: 31.5 | C20: 1023.5 | D20: 0.02 | E20: 22.94 | F20: 45.82 | G20: 68.69 | H20: 91.54 | I20: 114.21 | J20: =INDEX(LINEST($D$1:$I$1,$D20:$I20,,TRUE()),1) -> 0.43770663 | K20: =INDEX(LINEST($D$1:$I$1,$D20:$I20,,TRUE()),2) -> 0.00037376716 | L20: =INDEX(LINEST($D$1:$I$1,$D20:$I20,,TRUE()),3) -> 0.99999708
A21: 5027 output (mV) | B21: 27.6 | C21: 1008.6 | D21: 0.08 | E21: 22.89 | F21: 45.68 | G21: 68.48 | H21: 91.18 | I21: 113.81 | J21: =INDEX(LINEST($D$1:$I$1,$D21:$I21,,TRUE()),1) -> 0.43952078 | K21: =INDEX(LINEST($D$1:$I$1,$D21:$I21,,TRUE()),2) -> 0.0003352325 | L21: =INDEX(LINEST($D$1:$I$1,$D21:$I21,,TRUE()),3) -> 0.99999767 | M21: THU_L
A22: 5028 output (mV) | B22: 24.9 | C22: 999.9 | D22: -0.19 | E22: 23 | F22: 46.18 | G22: 69.34 | H22: 92.45 | I22: 115.43 | J22: =INDEX(LINEST($D$1:$I$1,$D22:$I22,,TRUE()),1) -> 0.43230581 | K22: =INDEX(LINEST($D$1:$I$1,$D22:$I22,,TRUE()),2) -> 0.00034519835 | L22: =INDEX(LINEST($D$1:$I$1,$D22:$I22,,TRUE()),3) -> 0.99999745 | N22: MIT | O22: MIT
A23: 5029 output (mV) | B23: 24.9 | C23: 999.9 | D23: -0.2 | E23: 22.81 | F23: 45.79 | G23: 68.76 | H23: 91.69 | I23: 114.5 | J23: =INDEX(LINEST($D$1:$I$1,$D23:$I23,,TRUE()),1) -> 0.4358049 | K23: =INDEX(LINEST($D$1:$I$1,$D23:$I23,,TRUE()),2) -> 0.00031389185 | L23: =INDEX(LINEST($D$1:$I$1,$D23:$I23,,TRUE()),3) -> 0.99999792 | M23: QAS_L | P23: KAN_Lv3
A24: 5030 output (mV) | B24: 24.9 | C24: 998.8 | D24: -0.18 | E24: 23.18 | F24: 46.52 | G24: 69.84 | H24: 93.12 | I24: 116.24 | J24: =INDEX(LINEST($D$1:$I$1,$D24:$I24,,TRUE()),1) -> 0.42932014 | K24: =INDEX(LINEST($D$1:$I$1,$D24:$I24,,TRUE()),2) -> 0.00037148046 | L24: =INDEX(LINEST($D$1:$I$1,$D24:$I24,,TRUE()),3) -> 0.99999701
A25: 5031 output (mV) | B25: 25.3 | C25: 1013.5 | D25: -0.33 | E25: 24.95 | F25: 50.22 | G25: 75.5 | H25: 100.72 | I25: 125.84 | J25: =INDEX(LINEST($D$1:$I$1,$D25:$I25,,TRUE()),1) -> 0.39617806 | K25: =INDEX(LINEST($D$1:$I$1,$D25:$I25,,TRUE()),2) -> 0.00022598167 | L25: =INDEX(LINEST($D$1:$I$1,$D25:$I25,,TRUE()),3) -> 0.9999987
A26: 5032 output (mV) | B26: 25.3 | C26: 1013.5 | D26: 0.06 | E26: 22.87 | F26: 45.65 | G26: 68.4 | H26: 91.1 | I26: 113.7 | J26: =INDEX(LINEST($D$1:$I$1,$D26:$I26,,TRUE()),1) -> 0.4398963 | K26: =INDEX(LINEST($D$1:$I$1,$D26:$I26,,TRUE()),2) -> 0.00035355742 | L26: =INDEX(LINEST($D$1:$I$1,$D26:$I26,,TRUE()),3) -> 0.99999742
A27: 5034 output (mV) | B27: 26.4 | C27: 1016.9 | D27: 0.2 | E27: 25.91 | F27: 51.65 | G27: 77.35 | H27: 103.02 | I27: 128.54 | J27: =INDEX(LINEST($D$1:$I$1,$D27:$I27,,TRUE()),1) -> 0.38943767 | K27: =INDEX(LINEST($D$1:$I$1,$D27:$I27,,TRUE()),2) -> 0.00027178526 | L27: =INDEX(LINEST($D$1:$I$1,$D27:$I27,,TRUE()),3) -> 0.99999805
A28: 5082 output (mV) | B28: 24.3 | C28: 1006.7 | D28: 0.31 | E28: 24.53 | F28: 48.71 | G28: 72.89 | H28: 97.03 | I28: 121.04 | J28: =INDEX(LINEST($D$1:$I$1,$D28:$I28,,TRUE()),1) -> 0.41403868 | K28: =INDEX(LINEST($D$1:$I$1,$D28:$I28,,TRUE()),2) -> 0.00028861928 | L28: =INDEX(LINEST($D$1:$I$1,$D28:$I28,,TRUE()),3) -> 0.99999806
A29: 5083 output (mV) | B29: 2403 | C29: 1006.7 | D29: -0.26 | E29: 23.64 | F29: 47.54 | G29: 71.46 | H29: 95.37 | I29: 119.06 | J29: =INDEX(LINEST($D$1:$I$1,$D29:$I29,,TRUE()),1) -> 0.41880464 | K29: =INDEX(LINEST($D$1:$I$1,$D29:$I29,,TRUE()),2) -> 0.000310718 | L29: =INDEX(LINEST($D$1:$I$1,$D29:$I29,,TRUE()),3) -> 0.9999978
A30: 5084 output (mV) | B30: 24.3 | C30: 1006.7 | D30: -0.24 | E30: 24.17 | F30: 48.56 | G30: 72.94 | H30: 97.25 | I30: 121.46 | J30: =INDEX(LINEST($D$1:$I$1,$D30:$I30,,TRUE()),1) -> 0.41073937 | K30: =INDEX(LINEST($D$1:$I$1,$D30:$I30,,TRUE()),2) -> 0.00030386418 | L30: =INDEX(LINEST($D$1:$I$1,$D30:$I30,,TRUE()),3) -> 0.99999781
A31: 5085 output (mV) | B31: 24.3 | C31: 1006.9 | D31: -0.39 | E31: 35.82 | F31: 71.86 | G31: 107.71 | H31: 143.2 | I31: 178.26 | J31: =INDEX(LINEST($D$1:$I$1,$D31:$I31,,TRUE()),1) -> 0.27971287 | K31: =INDEX(LINEST($D$1:$I$1,$D31:$I31,,TRUE()),2) -> 0.0008211142 | L31: =INDEX(LINEST($D$1:$I$1,$D31:$I31,,TRUE()),3) -> 0.99996553
A32: 5086 output (mV) | B32: 24.3 | C32: 1006.9 | D32: 0.03 | E32: 25.4 | F32: 50.84 | G32: 76.23 | H32: 101.54 | I32: 126.8 | J32: =INDEX(LINEST($D$1:$I$1,$D32:$I32,,TRUE()),1) -> 0.39429451 | K32: =INDEX(LINEST($D$1:$I$1,$D32:$I32,,TRUE()),2) -> 0.00024286295 | L32: =INDEX(LINEST($D$1:$I$1,$D32:$I32,,TRUE()),3) -> 0.99999848
A33: 5087 output (mV) | B33: 24.3 | C33: 1006.9 | D33: 0.01 | E33: 24.98 | F33: 49.98 | G33: 74.99 | H33: 100.01 | I33: 124.87 | J33: =INDEX(LINEST($D$1:$I$1,$D33:$I33,,TRUE()),1) -> 0.40027416 | K33: =INDEX(LINEST($D$1:$I$1,$D33:$I33,,TRUE()),2) -> 0.00017749047 | L33: =INDEX(LINEST($D$1:$I$1,$D33:$I33,,TRUE()),3) -> 0.99999921 | N33: TAS_L | O33: TAS_L | Q33: QAS_Lv3 | T33: Not working
A34: 5104 output (mV) | B34: 22.3 | C34: 1007 | D34: -0.21 | E34: 19.03 | F34: 38.37 | G34: 57.74 | H34: 77.09 | I34: 96.4 | J34: =INDEX(LINEST($D$1:$I$1,$D34:$I34,,TRUE()),1) -> 0.51729188 | K34: =INDEX(LINEST($D$1:$I$1,$D34:$I34,,TRUE()),2) -> 0.0002459653 | L34: =INDEX(LINEST($D$1:$I$1,$D34:$I34,,TRUE()),3) -> 0.9999991
A35: 5105 output (mV) | B35: 22.3 | C35: 1007 | D35: -0.2 | E35: 19.27 | F35: 38.88 | G35: 58.49 | H35: 78.08 | I35: 97.59 | J35: =INDEX(LINEST($D$1:$I$1,$D35:$I35,,TRUE()),1) -> 0.51095576 | K35: =INDEX(LINEST($D$1:$I$1,$D35:$I35,,TRUE()),2) -> 0.00027870308 | L35: =INDEX(LINEST($D$1:$I$1,$D35:$I35,,TRUE()),3) -> 0.99999881
A36: 5112 output (mV) | B36: 23.1 | C36: 992 | D36: -0.099 | E36: 19.704 | F36: 39.546 | G36: 59.377 | H36: 79.159 | I36: 98.838 | J36: =INDEX(LINEST($D$1:$I$1,$D36:$I36,,TRUE()),1) -> 0.50513632 | K36: =INDEX(LINEST($D$1:$I$1,$D36:$I36,,TRUE()),2) -> 0.00034207276 | L36: =INDEX(LINEST($D$1:$I$1,$D36:$I36,,TRUE()),3) -> 0.99999817
A37: 5113 output (mV) | B37: 23.1 | C37: 992 | D37: -0.046 | E37: 19.958 | F37: 40.051 | G37: 60.183 | H37: 80.31 | I37: 100.37 | J37: =INDEX(LINEST($D$1:$I$1,$D37:$I37,,TRUE()),1) -> 0.49767609 | K37: =INDEX(LINEST($D$1:$I$1,$D37:$I37,,TRUE()),2) -> 0.00024210663 | L37: =INDEX(LINEST($D$1:$I$1,$D37:$I37,,TRUE()),3) -> 0.99999905
A38: 5114 output (mV) | B38: 23.1 | C38: 992 | D38: -0.262 | E38: 19.332 | F38: 38.988 | G38: 58.655 | H38: 78.282 | I38: 97.828 | J38: =INDEX(LINEST($D$1:$I$1,$D38:$I38,,TRUE()),1) -> 0.50948547 | K38: =INDEX(LINEST($D$1:$I$1,$D38:$I38,,TRUE()),2) -> 0.00023420283 | L38: =INDEX(LINEST($D$1:$I$1,$D38:$I38,,TRUE()),3) -> 0.99999915
A39: 5115 output (mV) | B39: 26.1 | C39: 1022 | D39: 0.594 | E39: 18.732 | F39: 36.945 | G39: 55.195 | H39: 73.455 | I39: 91.682 | J39: =INDEX(LINEST($D$1:$I$1,$D39:$I39,,TRUE()),1) -> 0.54870996 | K39: =INDEX(LINEST($D$1:$I$1,$D39:$I39,,TRUE()),2) -> 0.00029927844 | L39: =INDEX(LINEST($D$1:$I$1,$D39:$I39,,TRUE()),3) -> 0.99999881
A40: 5116 output (mV) | B40: 26.1 | C40: 1022 | D40: 0.465 | E40: 20.296 | F40: 40.218 | G40: 60.192 | H40: 80.155 | I40: 100.052 | J40: =INDEX(LINEST($D$1:$I$1,$D40:$I40,,TRUE()),1) -> 0.5018016 | K40: =INDEX(LINEST($D$1:$I$1,$D40:$I40,,TRUE()),2) -> 0.00027234926 | L40: =INDEX(LINEST($D$1:$I$1,$D40:$I40,,TRUE()),3) -> 0.99999882 | P40: UPE_U
...
